<?xml version="1.0" encoding="utf-8"?>
 <!-- This URDF was automatically created by SolidWorks to URDF Exporter! Originally created by Stephen Brawner (brawner@gmail.com) 
      Commit Version: 1.6.0-4-g7f85cfe  Build Version: 1.6.7995.38578
      For more information, please see http://wiki.ros.org/sw_urdf_exporter -->
 <robot name="LiteArm_A10_251125">
  <mujoco>
    <compiler meshdir="../meshes/" balanceinertia="true" discardvisual="false" inertiafromgeom="false" fusestatic="false" />

  </mujoco>

   <link name="base_link">
     <inertial>
       <origin xyz="0.0 0.0 0.05542218" rpy="0 0 0" />
       <mass value="10.57317707" />
       <inertia ixx="0.35705741" ixy="0.0" ixz="0.0" iyy="0.35705741" iyz="0.0" izz="0.13447021" />
     </inertial>
     <visual>
       <origin xyz="0 0 0" rpy="0 0 0" />
       <geometry>
         <mesh filename="package://litearm_a10_251125/meshes/base_link.STL" />
       </geometry>
       <material name="">
         <color rgba="0.752941176470588 0.752941176470588 0.752941176470588 1" />
       </material>
     </visual>
     <collision>
       <origin xyz="0 0 0" rpy="0 0 0" />
       <geometry>
         <mesh filename="package://litearm_a10_251125/meshes/base_link_simplify.STL" />
       </geometry>
     </collision>
   </link>
   <link name="torso_link">
     <inertial>
       <origin xyz="7.642e-05 0.0 0.00012173" rpy="0 0 0" />
       <mass value="1.94711343" />
       <inertia ixx="0.01104026" ixy="4.23e-06" ixz="-3.57e-06" iyy="0.0021223" iyz="0.0" izz="0.01091172" />
     </inertial>
     <visual>
       <origin xyz="0 0 0" rpy="0 0 0" />
       <geometry>
         <mesh filename="package://litearm_a10_251125/meshes/torso_link.STL" />
       </geometry>
       <material name="">
         <color rgba="0.752941176470588 0.752941176470588 0.752941176470588 1" />
       </material>
     </visual>
     <collision>
       <origin xyz="0 0 0" rpy="0 0 0" />
       <geometry>
         <mesh filename="package://litearm_a10_251125/meshes/torso_link_simplify.STL" />
       </geometry>
     </collision>
   </link>
   <joint name="torso_joint" type="fixed">
     <origin xyz="0 0 0.7" rpy="0 0 0" />
     <parent link="base_link" />
     <child link="torso_link" />
     <axis xyz="0 0 0" />
     <dynamics damping="0.02" friction="0.0"/> <!-- 即使很小的阻尼也能极大改善稳定性 -->
   </joint>
   <link name="l_joint1_link">
     <inertial>
       <origin xyz="-0.00824806 0.05407816 6.022e-05" rpy="0 0 0" />
       <mass value="0.9772017" />
       <inertia ixx="0.00114572" ixy="3.314e-05" ixz="-5e-07" iyy="0.00086384" iyz="-1.53e-06" izz="0.0010431" />
     </inertial>
     <visual>
       <origin xyz="0 0 0" rpy="0 0 0" />
       <geometry>
         <mesh filename="package://litearm_a10_251125/meshes/l_joint1_link.STL" />
       </geometry>
       <material name="">
         <color rgba="0.752941176470588 0.752941176470588 0.752941176470588 1" />
       </material>
     </visual>
     <collision>
       <origin xyz="0 0 0" rpy="0 0 0" />
       <geometry>
         <mesh filename="package://litearm_a10_251125/meshes/l_joint1_link_simplify.STL" />
       </geometry>
     </collision>
   </link>
   <joint name="l_joint1_joint" type="revolute">
     <origin xyz="0 0.096 0" rpy="0 0 0" />
     <parent link="torso_link" />
     <child link="l_joint1_link" />
     <axis xyz="0 1 0" />
     <limit lower="-3.0543" upper="1.6581" effort="75" velocity="6.0737" />
     <dynamics damping="0.02" friction="0.0"/> <!-- 即使很小的阻尼也能极大改善稳定性 -->
   </joint>
   <link name="l_joint2_link">
     <inertial>
       <origin xyz="-0.02317012 0.0 -0.03968965" rpy="0 0 0" />
       <mass value="0.09956239" />
       <inertia ixx="7.689e-05" ixy="0.0" ixz="2.394e-05" iyy="9.208e-05" iyz="0.0" izz="4.871e-05" />
     </inertial>
     <visual>
       <origin xyz="0 0 0" rpy="0 0 0" />
       <geometry>
         <mesh filename="package://litearm_a10_251125/meshes/l_joint2_link.STL" />
       </geometry>
       <material name="">
         <color rgba="0.752941176470588 0.752941176470588 0.752941176470588 1" />
       </material>
     </visual>
     <collision>
       <origin xyz="0 0 0" rpy="0 0 0" />
       <geometry>
         <mesh filename="package://litearm_a10_251125/meshes/l_joint2_link.STL" />
       </geometry>
     </collision>
   </link>
   <joint name="l_joint2_joint" type="revolute">
     <origin xyz="0 0.059 0" rpy="0 0 0" />
     <parent link="l_joint1_link" />
     <child link="l_joint2_link" />
     <axis xyz="1 0 0" />
     <limit lower="-0.27925" upper="2.8623" effort="75" velocity="6.0737" />
     <dynamics damping="0.02" friction="0.0"/> <!-- 即使很小的阻尼也能极大改善稳定性 -->
   </joint>
   <link name="l_joint3_link">
     <inertial>
       <origin xyz="-0.00293915 -0.00086627 -0.09125362" rpy="0 0 0" />
       <mass value="0.31334613" />
       <inertia ixx="0.00166426" ixy="4e-07" ixz="-1.14e-05" iyy="0.00155026" iyz="-1.701e-05" izz="0.00033935" />
     </inertial>
     <visual>
       <origin xyz="0 0 0" rpy="0 0 0" />
       <geometry>
         <mesh filename="package://litearm_a10_251125/meshes/l_joint3_link.STL" />
       </geometry>
       <material name="">
         <color rgba="0.752941176470588 0.752941176470588 0.752941176470588 1" />
       </material>
     </visual>
     <collision>
       <origin xyz="0 0 0" rpy="0 0 0" />
       <geometry>
         <mesh filename="package://litearm_a10_251125/meshes/l_joint3_link.STL" />
       </geometry>
     </collision>
   </link>
   <joint name="l_joint3_joint" type="revolute">
     <origin xyz="0.00075 0 -0.0646" rpy="0 0 0" />
     <parent link="l_joint2_link" />
     <child link="l_joint3_link" />
     <axis xyz="0 0 1" />
     <limit lower="-1.5708" upper="1.5708" effort="50" velocity="6.0737" />
     <dynamics damping="0.02" friction="0.0"/> <!-- 即使很小的阻尼也能极大改善稳定性 -->
   </joint>
   <link name="l_joint4_link">
     <inertial>
       <origin xyz="-0.00122074 -0.00107776 -0.05909915" rpy="0 0 0" />
       <mass value="0.35219749" />
       <inertia ixx="0.0004984" ixy="1.9e-07" ixz="6.97e-06" iyy="0.00035525" iyz="2.099e-05" izz="0.00020903" />
     </inertial>
     <visual>
       <origin xyz="0 0 0" rpy="0 0 0" />
       <geometry>
         <mesh filename="package://litearm_a10_251125/meshes/l_joint4_link.STL" />
       </geometry>
       <material name="">
         <color rgba="0.752941176470588 0.752941176470588 0.752941176470588 1" />
       </material>
     </visual>
     <collision>
       <origin xyz="0 0 0" rpy="0 0 0" />
       <geometry>
         <mesh filename="package://litearm_a10_251125/meshes/l_joint4_link.STL" />
       </geometry>
     </collision>
   </link>
   <joint name="l_joint4_joint" type="revolute">
     <origin xyz="0 -5E-05 -0.1615" rpy="0 0 0" />
     <parent link="l_joint3_link" />
     <child link="l_joint4_link" />
     <axis xyz="0 1 0" />
     <limit lower="-2.4435" upper="1.5708" effort="50" velocity="6.0737" />
     <dynamics damping="0.02" friction="0.0"/> <!-- 即使很小的阻尼也能极大改善稳定性 -->
   </joint>
   <link name="l_joint5_link">
     <inertial>
       <origin xyz="-0.00301628 -0.00024339 -0.04784072" rpy="0 0 0" />
       <mass value="0.42918472" />
       <inertia ixx="0.00022593" ixy="2.8e-07" ixz="1.107e-05" iyy="0.0002748" iyz="-3.5e-07" izz="0.0001236" />
     </inertial>
     <visual>
       <origin xyz="0 0 0" rpy="0 0 0" />
       <geometry>
         <mesh filename="package://litearm_a10_251125/meshes/l_joint5_link.STL" />
       </geometry>
       <material name="">
         <color rgba="0.752941176470588 0.752941176470588 0.752941176470588 1" />
       </material>
     </visual>
     <collision>
       <origin xyz="0 0 0" rpy="0 0 0" />
       <geometry>
         <mesh filename="package://litearm_a10_251125/meshes/l_joint5_link.STL" />
       </geometry>
     </collision>
   </link>
   <joint name="l_joint5_joint" type="revolute">
     <origin xyz="0 0 -0.094" rpy="0 0 0" />
     <parent link="l_joint4_link" />
     <child link="l_joint5_link" />
     <axis xyz="0 0 1" />
     <limit lower="-1.5708" upper="1.5708" effort="10" velocity="10.263" />
     <dynamics damping="0.02" friction="0.0"/> <!-- 即使很小的阻尼也能极大改善稳定性 -->
   </joint>
   <link name="l_joint6_link">
     <inertial>
       <origin xyz="-0.00042158 0.00237788 -0.00011028" rpy="0 0 0" />
       <mass value="0.26605252" />
       <inertia ixx="0.00010511" ixy="-2e-07" ixz="4.4e-07" iyy="0.00010704" iyz="-1.4e-07" izz="0.0001287" />
     </inertial>
     <visual>
       <origin xyz="0 0 0" rpy="0 0 0" />
       <geometry>
         <mesh filename="package://litearm_a10_251125/meshes/l_joint6_link.STL" />
       </geometry>
       <material name="">
         <color rgba="0.752941176470588 0.752941176470588 0.752941176470588 1" />
       </material>
     </visual>
     <collision>
       <origin xyz="0 0 0" rpy="0 0 0" />
       <geometry>
         <mesh filename="package://litearm_a10_251125/meshes/l_joint6_link.STL" />
       </geometry>
     </collision>
   </link>
   <joint name="l_joint6_joint" type="revolute">
     <origin xyz="0 0 -0.1255" rpy="0 0 0" />
     <parent link="l_joint5_link" />
     <child link="l_joint6_link" />
     <axis xyz="1 0 0" />
     <limit lower="-0.76794" upper="0.76794" effort="20" velocity="6.2832" />
     <dynamics damping="0.02" friction="0.0"/> <!-- 即使很小的阻尼也能极大改善稳定性 -->
   </joint>
   <link name="l_joint7_link">
     <inertial>
       <origin xyz="-8.567e-05 0.00077068 -0.06260654" rpy="0 0 0" />
       <mass value="0.23310292" />
       <inertia ixx="0.00019703" ixy="4.3e-07" ixz="-1.6e-07" iyy="0.00017465" iyz="-1.298e-05" izz="0.0001016" />
     </inertial>
     <visual>
       <origin xyz="0 0 0" rpy="0 0 0" />
       <geometry>
         <mesh filename="package://litearm_a10_251125/meshes/l_joint7_link.STL" />
       </geometry>
       <material name="">
         <color rgba="0.752941176470588 0.752941176470588 0.752941176470588 1" />
       </material>
     </visual>
     <collision>
       <origin xyz="0 0 0" rpy="0 0 0" />
       <geometry>
         <mesh filename="package://litearm_a10_251125/meshes/l_joint7_link_simplify.STL" />
       </geometry>
     </collision>
   </link>
   <joint name="l_joint7_joint" type="revolute">
     <origin xyz="0 0 0" rpy="0 0 0" />
     <parent link="l_joint6_link" />
     <child link="l_joint7_link" />
     <axis xyz="0 1 0" />
     <limit lower="-1.5708" upper="1.5708" effort="10" velocity="10.263" />
     <dynamics damping="0.02" friction="0.0"/> <!-- 即使很小的阻尼也能极大改善稳定性 -->
   </joint>
   <link name="l_gripper_link">
     <inertial>
       <origin xyz="6.03e-06 1.102e-05 -0.01065717" rpy="0 0 0" />
       <mass value="0.11713645" />
       <inertia ixx="0.00016864" ixy="-2.14e-06" ixz="0.0" iyy="1.602e-05" iyz="0.0" izz="0.00017264" />
     </inertial>
     <visual>
       <origin xyz="0 0 0" rpy="0 0 0" />
       <geometry>
         <mesh filename="package://litearm_a10_251125/meshes/l_gripper_link.STL" />
       </geometry>
       <material name="">
         <color rgba="0.752941176470588 0.752941176470588 0.752941176470588 1" />
       </material>
     </visual>
     <collision>
       <origin xyz="0 0 0" rpy="0 0 0" />
       <geometry>
         <mesh filename="package://litearm_a10_251125/meshes/l_gripper_link.STL" />
       </geometry>
     </collision>
   </link>
   <joint name="l_gripper_joint" type="fixed">
     <origin xyz="0 0 -0.09015" rpy="0 0 0" />
     <parent link="l_joint7_link" />
     <child link="l_gripper_link" />
     <axis xyz="0 0 0" />
     <limit effort="10" velocity="10.2625360017267" />
     <dynamics damping="0.02" friction="0.0"/> <!-- 即使很小的阻尼也能极大改善稳定性 -->
   </joint>
     <!-- Define the hand_tcp frame -->
  <link name="l_hand_tcp_link"/>
  <joint name="l_hand_tcp__joint" type="fixed">
    <origin rpy="0 0 0" xyz="0 0 0.0845"/>
    <parent link="l_gripper_link"/>
    <child link="l_hand_tcp_link"/>
    <dynamics damping="0.02" friction="0.0"/> <!-- 即使很小的阻尼也能极大改善稳定性 -->
   </joint>

   <link name="l_r_finger_link">
     <inertial>
       <origin xyz="7.42e-05 -0.01775832 -0.027404" rpy="0 0 0" />
       <mass value="0.0948599" />
       <inertia ixx="5.702e-05" ixy="8e-08" ixz="-1.3e-07" iyy="5.837e-05" iyz="3.24e-06" izz="1.536e-05" />
     </inertial>
     <visual>
       <origin xyz="0 0 0" rpy="0 0 0" />
       <geometry>
         <mesh filename="package://litearm_a10_251125/meshes/l_r_finger_link.STL" />
       </geometry>
       <material name="">
         <color rgba="0.752941176470588 0.752941176470588 0.752941176470588 1" />
       </material>
     </visual>
     <collision>
       <origin xyz="0 0 0" rpy="0 0 0" />
       <geometry>
         <mesh filename="package://litearm_a10_251125/meshes/l_r_finger_link.STL" />
       </geometry>
     </collision>
   </link>
   <joint name="l_r_finger_joint" type="prismatic">
     <origin xyz="0 0 -0.0185" rpy="0 0 0" />
     <parent link="l_gripper_link" />
     <child link="l_r_finger_link" />
     <axis xyz="0 -1 0" />
     <limit lower="0" upper="0.0475" effort="10" velocity="10.263" />
     
     <dynamics damping="0.02" friction="0.0"/> <!-- 即使很小的阻尼也能极大改善稳定性 -->
   </joint>
   <link name="l_l_finger_link">
     <inertial>
       <origin xyz="-7.42e-05 0.01775832 -0.027404" rpy="0 0 0" />
       <mass value="0.0948599" />
       <inertia ixx="5.702e-05" ixy="8e-08" ixz="1.4e-07" iyy="5.837e-05" iyz="-3.24e-06" izz="1.536e-05" />
     </inertial>
     <visual>
       <origin xyz="0 0 0" rpy="0 0 0" />
       <geometry>
         <mesh filename="package://litearm_a10_251125/meshes/l_l_finger_link.STL" />
       </geometry>
       <material name="">
         <color rgba="0.752941176470588 0.752941176470588 0.752941176470588 1" />
       </material>
     </visual>
     <collision>
       <origin xyz="0 0 0" rpy="0 0 0" />
       <geometry>
         <mesh filename="package://litearm_a10_251125/meshes/l_l_finger_link.STL" />
       </geometry>
     </collision>
   </link>
   <joint name="l_l_finger_joint" type="prismatic">
     <origin xyz="0 0 -0.0185" rpy="0 0 0" />
     <parent link="l_gripper_link" />
     <child link="l_l_finger_link" />
     <axis xyz="0 1 0" />
     <limit lower="0" upper="0.0475" effort="10" velocity="10.263" />
     <mimic joint="l_r_finger_joint" multiplier="1.0" offset="0.0"/>
     <dynamics damping="0.02" friction="0.0"/> <!-- 即使很小的阻尼也能极大改善稳定性 -->
   </joint>
   <link name="r_joint1_link">
     <inertial>
       <origin xyz="-0.00824806 -0.05412006 3.006e-05" rpy="0 0 0" />
       <mass value="0.9772017" />
       <inertia ixx="0.00114613" ixy="-3.447e-05" ixz="4.4e-07" iyy="0.00086384" iyz="-1.1e-06" izz="0.0010435" />
     </inertial>
     <visual>
       <origin xyz="0 0 0" rpy="0 0 0" />
       <geometry>
         <mesh filename="package://litearm_a10_251125/meshes/r_joint1_link.STL" />
       </geometry>
       <material name="">
         <color rgba="0.752941176470588 0.752941176470588 0.752941176470588 1" />
       </material>
     </visual>
     <collision>
       <origin xyz="0 0 0" rpy="0 0 0" />
       <geometry>
         <mesh filename="package://litearm_a10_251125/meshes/r_joint1_link_simplify.STL" />
       </geometry>
     </collision>
   </link>
   <joint name="r_joint1_joint" type="revolute">
     <origin xyz="0 -0.096 0" rpy="0 0 0" />
     <parent link="torso_link" />
     <child link="r_joint1_link" />
     <axis xyz="0 -1 0" />
     <limit lower="-1.6581" upper="3.0543" effort="75" velocity="6.0737" />  <!-- 改了 -->
     <dynamics damping="0.02" friction="0.0"/> <!-- 即使很小的阻尼也能极大改善稳定性 -->
   </joint>
   <link name="r_joint2_link">
     <inertial>
       <origin xyz="-0.02317012 0.0 -0.03968965" rpy="0 0 0" />
       <mass value="0.09956239" />
       <inertia ixx="7.689e-05" ixy="0.0" ixz="2.394e-05" iyy="9.208e-05" iyz="0.0" izz="4.871e-05" />
     </inertial>
     <visual>
       <origin xyz="0 0 0" rpy="0 0 0" />
       <geometry>
         <mesh filename="package://litearm_a10_251125/meshes/r_joint2_link.STL" />
       </geometry>
       <material name="">
         <color rgba="0.752941176470588 0.752941176470588 0.752941176470588 1" />
       </material>
     </visual>
     <collision>
       <origin xyz="0 0 0" rpy="0 0 0" />
       <geometry>
         <mesh filename="package://litearm_a10_251125/meshes/r_joint2_link.STL" />
       </geometry>
     </collision>
   </link>
   <joint name="r_joint2_joint" type="revolute">
     <origin xyz="0 -0.059 0" rpy="0 0 0" />
     <parent link="r_joint1_link" />
     <child link="r_joint2_link" />
     <axis xyz="-1 0 0" />
     <limit lower="-0.27925" upper="2.8623" effort="75" velocity="6.0737" />   <!-- 改了 -->
     <dynamics damping="0.02" friction="0.0"/> <!-- 即使很小的阻尼也能极大改善稳定性 -->
   </joint>
   <link name="r_joint3_link">
     <inertial>
       <origin xyz="-0.00270323 0.00075972 -0.09125362" rpy="0 0 0" />
       <mass value="0.31334613" />
       <inertia ixx="0.00166431" ixy="-1.04e-06" ixz="-6.83e-06" iyy="0.00155067" iyz="1.881e-05" izz="0.00033982" />
     </inertial>
     <visual>
       <origin xyz="0 0 0" rpy="0 0 0" />
       <geometry>
         <mesh filename="package://litearm_a10_251125/meshes/r_joint3_link.STL" />
       </geometry>
       <material name="">
         <color rgba="0.752941176470588 0.752941176470588 0.752941176470588 1" />
       </material>
     </visual>
     <collision>
       <origin xyz="0 0 0" rpy="0 0 0" />
       <geometry>
         <mesh filename="package://litearm_a10_251125/meshes/r_joint3_link.STL" />
       </geometry>
     </collision>
   </link>
   <joint name="r_joint3_joint" type="revolute">
     <origin xyz="-0.00468 -0.0044713 -0.06468" rpy="0 0 0" />
     <parent link="r_joint2_link" />
     <child link="r_joint3_link" />
     <axis xyz="0 0 -1" />
     <limit lower="-1.5708" upper="1.5708" effort="50" velocity="6.0737" />
     <dynamics damping="0.02" friction="0.0"/> <!-- 即使很小的阻尼也能极大改善稳定性 -->
   </joint>
   <link name="r_joint4_link">
     <inertial>
       <origin xyz="-0.00123805 0.00095534 -0.05909395" rpy="0 0 0" />
       <mass value="0.35219749" />
       <inertia ixx="0.00049866" ixy="-7.5e-07" ixz="7.25e-06" iyy="0.00035545" iyz="-2.156e-05" izz="0.00020916" />
     </inertial>
     <visual>
       <origin xyz="0 0 0" rpy="0 0 0" />
       <geometry>
         <mesh filename="package://litearm_a10_251125/meshes/r_joint4_link.STL" />
       </geometry>
       <material name="">
         <color rgba="0.752941176470588 0.752941176470588 0.752941176470588 1" />
       </material>
     </visual>
     <collision>
       <origin xyz="0 0 0" rpy="0 0 0" />
       <geometry>
         <mesh filename="package://litearm_a10_251125/meshes/r_joint4_link.STL" />
       </geometry>
     </collision>
   </link>
   <joint name="r_joint4_joint" type="revolute">
     <origin xyz="0.00543 0.0045213 -0.16142" rpy="0 0 0" />
     <parent link="r_joint3_link" />
     <child link="r_joint4_link" />
     <axis xyz="0 -1 0" />
     <limit lower="-1.5708" upper="2.4435" effort="50" velocity="6.0737" /><!-- 改了 -->
     <dynamics damping="0.02" friction="0.0"/> <!-- 即使很小的阻尼也能极大改善稳定性 -->
   </joint>
   <link name="r_joint5_link">
     <inertial>
       <origin xyz="-0.00301628 -0.00024339 -0.04784072" rpy="0 0 0" />
       <mass value="0.42918472" />
       <inertia ixx="0.00022593" ixy="2.8e-07" ixz="1.107e-05" iyy="0.0002748" iyz="-3.5e-07" izz="0.0001236" />
     </inertial>
     <visual>
       <origin xyz="0 0 0" rpy="0 0 0" />
       <geometry>
         <mesh filename="package://litearm_a10_251125/meshes/r_joint5_link.STL" />
       </geometry>
       <material name="">
         <color rgba="0.752941176470588 0.752941176470588 0.752941176470588 1" />
       </material>
     </visual>
     <collision>
       <origin xyz="0 0 0" rpy="0 0 0" />
       <geometry>
         <mesh filename="package://litearm_a10_251125/meshes/r_joint5_link.STL" />
       </geometry>
     </collision>
   </link>
   <joint name="r_joint5_joint" type="revolute">
     <origin xyz="-0.00543 -0.0044713 -0.09408" rpy="0 0 0" />
     <parent link="r_joint4_link" />
     <child link="r_joint5_link" />
     <axis xyz="0 0 -1" />
     <limit lower="-1.5708" upper="1.5708" effort="10" velocity="10.263" />
     <dynamics damping="0.02" friction="0.0"/> <!-- 即使很小的阻尼也能极大改善稳定性 -->
   </joint>
   <link name="r_joint6_link">
     <inertial>
       <origin xyz="-0.00042158 -0.00237788 0.00010463" rpy="0 0 0" />
       <mass value="0.26605252" />
       <inertia ixx="0.00010511" ixy="2e-07" ixz="-4.9e-07" iyy="0.00010704" iyz="-1.3e-07" izz="0.0001287" />
     </inertial>
     <visual>
       <origin xyz="0 0 0" rpy="0 0 0" />
       <geometry>
         <mesh filename="package://litearm_a10_251125/meshes/r_joint6_link.STL" />
       </geometry>
       <material name="">
         <color rgba="0.752941176470588 0.752941176470588 0.752941176470588 1" />
       </material>
     </visual>
     <collision>
       <origin xyz="0 0 0" rpy="0 0 0" />
       <geometry>
         <mesh filename="package://litearm_a10_251125/meshes/r_joint6_link.STL" />
       </geometry>
     </collision>
   </link>
   <joint name="r_joint6_joint" type="revolute">
     <origin xyz="0.00543 0.0044713 -0.12542" rpy="0 0 0" />
     <parent link="r_joint5_link" />
     <child link="r_joint6_link" />
     <axis xyz="-1 0 0" />
     <limit lower="-0.76794" upper="0.76794" effort="20" velocity="6.2832" />
     <dynamics damping="0.02" friction="0.0"/> <!-- 即使很小的阻尼也能极大改善稳定性 -->
   </joint>
   <link name="r_joint7_link">
     <inertial>
       <origin xyz="-8.715e-05 -0.00101597 -0.06260656" rpy="0 0 0" />
       <mass value="0.23310292" />
       <inertia ixx="0.00019693" ixy="4.7e-07" ixz="-1.4e-07" iyy="0.00017465" iyz="1.289e-05" izz="0.0001015" />
     </inertial>
     <visual>
       <origin xyz="0 0 0" rpy="0 0 0" />
       <geometry>
         <mesh filename="package://litearm_a10_251125/meshes/r_joint7_link.STL" />
       </geometry>
       <material name="">
         <color rgba="0.752941176470588 0.752941176470588 0.752941176470588 1" />
       </material>
     </visual>
     <collision>
       <origin xyz="0 0 0" rpy="0 0 0" />
       <geometry>
         <mesh filename="package://litearm_a10_251125/meshes/r_joint7_link_simplify.STL" />
       </geometry>
     </collision>
   </link>
   <joint name="r_joint7_joint" type="revolute">
     <origin xyz="0 0 0" rpy="0 0 0" />
     <parent link="r_joint6_link" />
     <child link="r_joint7_link" />
     <axis xyz="0 -1 0" />
     <limit lower="-1.5708" upper="1.5708" effort="10" velocity="10.263" />
     <dynamics damping="0.02" friction="0.0"/> <!-- 即使很小的阻尼也能极大改善稳定性 -->
   </joint>
   <link name="r_gripper_link">
     <inertial>
       <origin xyz="0.00543605 0.00448234 -0.01057694" rpy="0 0 0" />
       <mass value="0.11713645" />
       <inertia ixx="0.00016864" ixy="-2.14e-06" ixz="0.0" iyy="1.602e-05" iyz="0.0" izz="0.00017264" />
     </inertial>
     <visual>
       <origin xyz="0 0 0" rpy="0 0 0" />
       <geometry>
         <mesh filename="package://litearm_a10_251125/meshes/r_gripper_link.STL" />
       </geometry>
       <material name="">
         <color rgba="0.752941176470588 0.752941176470588 0.752941176470588 1" />
       </material>
     </visual>
     <collision>
       <origin xyz="0 0 0" rpy="0 0 0" />
       <geometry>
         <mesh filename="package://litearm_a10_251125/meshes/r_gripper_link.STL" />
       </geometry>
     </collision>
   </link>
   <joint name="r_gripper_joint" type="fixed">
     <origin xyz="-0.00543 -0.0044713 -0.09023" rpy="0 0 0" />
     <parent link="r_joint7_link" />
     <child link="r_gripper_link" />
     <axis xyz="0 0 0" />
     <limit effort="10" velocity="10.263" />
     <dynamics damping="0.02" friction="0.0"/> <!-- 即使很小的阻尼也能极大改善稳定性 -->
   </joint>
  <link name="r_hand_tcp_link"/>
  <joint name="r_hand_tcp__joint" type="fixed">
    <origin rpy="0 0 0" xyz="0 0 0.0845"/>
    <parent link="r_gripper_link"/>
    <child link="r_hand_tcp_link"/>
    <dynamics damping="0.02" friction="0.0"/> <!-- 即使很小的阻尼也能极大改善稳定性 -->
   </joint>
   <link name="r_r_finger_link">
     <inertial>
       <origin xyz="7.42e-05 -0.01775832 -0.027404" rpy="0 0 0" />
       <mass value="0.0948599" />
       <inertia ixx="5.702e-05" ixy="8e-08" ixz="-1.3e-07" iyy="5.837e-05" iyz="3.24e-06" izz="1.536e-05" />
     </inertial>
     <visual>
       <origin xyz="0 0 0" rpy="0 0 0" />
       <geometry>
         <mesh filename="package://litearm_a10_251125/meshes/r_r_finger_link.STL" />
       </geometry>
       <material name="">
         <color rgba="0.752941176470588 0.752941176470588 0.752941176470588 1" />
       </material>
     </visual>
     <collision>
       <origin xyz="0 0 0" rpy="0 0 0" />
       <geometry>
         <mesh filename="package://litearm_a10_251125/meshes/r_r_finger_link.STL" />
       </geometry>
     </collision>
   </link>
   <joint name="r_r_finger_joint" type="prismatic">
     <origin xyz="0.00543 0.0044713 -0.01842" rpy="0 0 0" />
     <parent link="r_gripper_link" />
     <child link="r_r_finger_link" />
     <axis xyz="0 -1 0" />
     <limit lower="0" upper="0.0475" effort="10" velocity="10.263" />
     
     <dynamics damping="0.02" friction="0.0"/> <!-- 即使很小的阻尼也能极大改善稳定性 -->
   </joint>
   <link name="r_l_finger_link">
     <inertial>
       <origin xyz="-7.42e-05 0.01775832 -0.027404" rpy="0 0 0" />
       <mass value="0.0948599" />
       <inertia ixx="5.702e-05" ixy="8e-08" ixz="1.4e-07" iyy="5.837e-05" iyz="-3.24e-06" izz="1.536e-05" />
     </inertial>
     <visual>
       <origin xyz="0 0 0" rpy="0 0 0" />
       <geometry>
         <mesh filename="package://litearm_a10_251125/meshes/r_l_finger_link.STL" />
       </geometry>
       <material name="">
         <color rgba="0.752941176470588 0.752941176470588 0.752941176470588 1" />
       </material>
     </visual>
     <collision>
       <origin xyz="0 0 0" rpy="0 0 0" />
       <geometry>
         <mesh filename="package://litearm_a10_251125/meshes/r_l_finger_link.STL" />
       </geometry>
     </collision>
   </link>
   <joint name="r_l_finger_joint" type="prismatic">
     <origin xyz="0.00543 0.0044713 -0.01842" rpy="0 0 0" />
     <parent link="r_gripper_link" />
     <child link="r_l_finger_link" />
     <axis xyz="0 1 0" />
     <limit lower="0.0" upper="0.0475" effort="10" velocity="10.263" />
     <mimic joint="r_r_finger_joint" multiplier="1.0" offset="0.0"/>
     <dynamics damping="0.02" friction="0.0"/> <!-- 即使很小的阻尼也能极大改善稳定性 -->
   </joint>

 </robot>
