<?xml version="1.0" encoding="utf-8"?>
<!-- Right arm only URDF for Pinocchio gravity compensation computation -->
<!-- Extracted from LiteArm_A10_251224.urdf, keeping only right arm kinematic chain -->
<robot name="LiteArm_A10_RightArm">
  <link name="base_link">
    <inertial>
      <origin xyz="0.0 0.0 0.05542218" rpy="0 0 0" />
      <mass value="10.57317707" />
      <inertia ixx="0.35705741" ixy="0.0" ixz="0.0" iyy="0.35705741" iyz="0.0" izz="0.13447021" />
    </inertial>
  </link>
  <link name="torso_link">
    <inertial>
      <origin xyz="0.00013737 0.0 0.00018058" rpy="0 0 0" />
      <mass value="2.04147618" />
      <inertia ixx="0.01168081" ixy="4.23e-06" ixz="-7.21e-06" iyy="0.00229997" iyz="0.0" izz="0.01155229" />
    </inertial>
  </link>
  <joint name="torso_joint" type="fixed">
    <origin xyz="0 0 0.7" rpy="0 0 0" />
    <parent link="base_link" />
    <child link="torso_link" />
  </joint>
  <link name="r_joint1_link">
    <inertial>
      <origin xyz="-0.00600738 -0.05288804 0.00023378" rpy="0 0 0" />
      <mass value="1.12932109" />
      <inertia ixx="0.00150342" ixy="-5.677e-05" ixz="-7e-07" iyy="0.00116586" iyz="-7.8e-07" izz="0.00137258" />
    </inertial>
  </link>
  <joint name="r_joint1_joint" type="revolute">
    <origin xyz="0 -0.096 0" rpy="0 0 0" />
    <parent link="torso_link" />
    <child link="r_joint1_link" />
    <axis xyz="0 1 0" />
    <limit lower="-3.0543" upper="1.6581" effort="75" velocity="6.0737" />
  </joint>
  <link name="r_joint2_link">
    <inertial>
      <origin xyz="-0.02317012 0.0 -0.03968965" rpy="0 0 0" />
      <mass value="0.09956239" />
      <inertia ixx="7.689e-05" ixy="0.0" ixz="2.394e-05" iyy="9.208e-05" iyz="0.0" izz="4.871e-05" />
    </inertial>
  </link>
  <joint name="r_joint2_joint" type="revolute">
    <origin xyz="0 -0.059 0" rpy="0 0 0" />
    <parent link="r_joint1_link" />
    <child link="r_joint2_link" />
    <axis xyz="1 0 0" />
    <limit lower="-2.8623" upper="0.27925" effort="75" velocity="6.0737" />
  </joint>
  <link name="r_joint3_link">
    <inertial>
      <origin xyz="-0.00411716 0.00049213 -0.08262124" rpy="0 0 0" />
      <mass value="0.48716788" />
      <inertia ixx="0.00231302" ixy="-5.8e-07" ixz="-3.282e-05" iyy="0.00218288" iyz="2.225e-05" izz="0.00065528" />
    </inertial>
  </link>
  <joint name="r_joint3_joint" type="revolute">
    <origin xyz="0.00075 0 -0.0646" rpy="0 0 0" />
    <parent link="r_joint2_link" />
    <child link="r_joint3_link" />
    <axis xyz="0 0 -1" />
    <limit lower="-1.5708" upper="1.5708" effort="50" velocity="6.0737" />
  </joint>
  <link name="r_joint4_link">
    <inertial>
      <origin xyz="-0.00192955 0.0007977 -0.05668517" rpy="0 0 0" />
      <mass value="0.42151988" />  <!-- 原来是0.42151988 -->
      <inertia ixx="0.0006874" ixy="-9.8e-07" ixz="3.96e-06" iyy="0.0004971" iyz="-2.077e-05" izz="0.00033631" />
    </inertial>
  </link>
  <joint name="r_joint4_joint" type="revolute">
    <origin xyz="0 5E-05 -0.1615" rpy="0 0 0" />
    <parent link="r_joint3_link" />
    <child link="r_joint4_link" />
    <axis xyz="0 1 0" />
    <limit lower="-2.44" upper="1.57" effort="50" velocity="6.0737" />
  </joint>
  <link name="r_joint5_link">
    <inertial>
      <origin xyz="-0.00434961 -0.00026606 -0.05218834" rpy="0 0 0" />
      <mass value="0.54640883" />  <!-- 原来是0.54640883 -->
      <inertia ixx="0.00051953" ixy="-8e-08" ixz="-1.146e-05" iyy="0.00060649" iyz="1e-06" izz="0.00028678" />
    </inertial>
  </link>
  <joint name="r_joint5_joint" type="revolute">
    <origin xyz="0 0 -0.094" rpy="0 0 0" />
    <parent link="r_joint4_link" />
    <child link="r_joint5_link" />
    <axis xyz="0 0 -1" />
    <limit lower="-1.5708" upper="1.5708" effort="10" velocity="10.263" />
  </joint>
  <link name="r_joint6_link">
    <inertial>
      <origin xyz="-0.00042158 -0.00237788 0.00010463" rpy="0 0 0" />
      <mass value="0.26605252" />
      <inertia ixx="0.00010511" ixy="2e-07" ixz="-4.9e-07" iyy="0.00010704" iyz="-1.3e-07" izz="0.0001287" />
    </inertial>
  </link>
  <joint name="r_joint6_joint" type="revolute">
    <origin xyz="0 0 -0.1255" rpy="0 0 0" />
    <parent link="r_joint5_link" />
    <child link="r_joint6_link" />
    <axis xyz="1 0 0" />
    <limit lower="-0.76794" upper="0.76794" effort="20" velocity="6.2832" />
  </joint>
  <link name="r_joint7_link">
    <inertial>
      <origin xyz="-3.036e-05 -0.00016972 -0.08950102" rpy="0 0 0" />
      <mass value="0.61408261" />
      <inertia ixx="0.00146206" ixy="-1.3e-06" ixz="2.9e-07" iyy="0.0011969" iyz="7.19e-06" izz="0.00044649" />
    </inertial>
  </link>
  <joint name="r_joint7_joint" type="revolute">
    <origin xyz="0 0 0" rpy="0 0 0" />
    <parent link="r_joint6_link" />
    <child link="r_joint7_link" />
    <axis xyz="0 1 0" />
    <limit lower="-1.5708" upper="1.5708" effort="10" velocity="10.263" />
  </joint>
</robot>
